#the try block will generate an exception,
#because x is not defined
try:
    print(x)
except:
    print("an exception occured")
